Workbook

Sheet Resumen
A1: NIHON — BASE MAESTRA v2 / JAPÓN 2027
A2: Base normalizada y verificada al 2026-09-01; conserva alternativas y separa confirmados, patrones históricos y pendientes 2027.
A4: Métrica | B4: Valor | D4: Métrica | E4: Valor | G4: Métrica | H4: Valor
A5: Total de fichas | B5: =COUNTA('Lugares'!$A$2:$A$500) | D5: Tokio | E5: =COUNTIF('Lugares'!$B$2:$B$500,"Tokio") | G5: Saturación extrema | H5: =COUNTIF('Lugares'!$U$2:$U$500,"Extremo")
A6: Grado S | B6: =COUNTA(Lugares!A2:A500) | D6: Kioto | E6: =COUNTIF('Lugares'!$B$2:$B$500,"Kioto") | G6: Impacto visual 5 | H6: =COUNTIF('Lugares'!$AM$2:$AM$500,5)
A7: Grado A | B7: =COUNTIF(Lugares!M2:M500,"S") | D7: Osaka/Kansai | E7: =COUNTIF('Lugares'!$B$2:$B$500,"Osaka") | G7: Naturaleza/mar | H7: =COUNTIF('Lugares'!$K$2:$K$500,"🌿 Naturaleza")+COUNTIF('Lugares'!$K$2:$K$500,"🌊 Playa/mar/islas")
A8: Hidden gems | B8: =COUNTIF(Lugares!M2:M500,"A") | D8: Okinawa | E8: =COUNTIF('Lugares'!$B$2:$B$500,"Okinawa") | G8: Gaming/anime | H8: =COUNTIF('Lugares'!$K$2:$K$500,"🎮 Videojuegos")+COUNTIF('Lugares'!$K$2:$K$500,"👾 Anime/manga")
A9: Requieren/recomiendan reserva | B9: =COUNTIF(Lugares!M2:M500,"B") | D9: Clusters | E9: =COUNTA('Clusters'!$A$2:$A$200) | G9: Cambios 2026 vigilados | H9: =COUNTA('Cambios 2026'!$A$2:$A$100)
B10: =COUNTIF(Lugares!M2:M500,"C")
B11: =COUNTIF(Lugares!M2:M500,"D")
A12: Cómo usar esta base
A13: 1 | B13: =COUNTIF(Lugares!AS2:AS500,"Semi-hidden")
A14: 2 | B14: Consulta Clusters y Cercanos para la futura función ‘Si estás aquí…’.
A15: 3 | B15: Hidden Gems distingue joya real, semi-hidden y alternativa.
A16: 4 | B16: Comparativas evita duplicar miradores, mercados, teamLab, castillos u onsen.
A17: 5 | B17: Feb-Mar 2027 reúne cierres, aperturas, riesgos invernales y oportunidades estacionales.
A18: Nota | B18: Precios MXN usan 1 JPY = 0.1060 MXN (Banxico, 2026-09-01). Horarios y tarifas variables deben verificarse al fijar fechas.

Sheet Lugares
A1: ID | B1: Hub | C1: Región | D1: Prefectura | E1: Municipio | F1: Zona/barrio | G1: Cluster | H1: Nombre oficial | I1: Nombre japonés | J1: Título mapa | K1: Categoría | L1: Tipo | M1: Grado | N1: Razón del grado | O1: Descripción corta | P1: Qué lo hace diferente | Q1: Qué se hace/ve | R1: Duración | S1: Mejor momento | T1: Mejor época | U1: Aglomeración | V1: Qué tan turístico | W1: Precio JPY mín | X1: Precio JPY máx | Y1: Precio MXN mín | Z1: Precio MXN máx | AA1: Reserva | AB1: Anticipación | AC1: Horario | AD1: Días de cierre | AE1: Estación/transporte útil | AF1: Accesibilidad aproximada | AG1: Latitud | AH1: Longitud | AI1: Página oficial/fuente | AJ1: Estado de información | AK1: Etiqueta | AL1: Ideal para | AM1: Impacto visual 1–5 | AN1: Originalidad 1–5 | AO1: Valor/tiempo 1–5 | AP1: Turismo 1–5 | AQ1: Imagen recomendada | AR1: Si estás aquí... | AS1: Hidden Gem Status | AT1: Alternativa a | AU1: Google Maps | AV1: Actualizado | AW1: Estado Feb–Mar 2027 | AX1: Advertencia / oportunidad Feb–Mar 2027 | AY1: Acción recomendada Feb–Mar 2027
A2: JP-001 | B2: Tokio | C2: Kanto | D2: Tokio | E2: Shibuya | F2: Shibuya | G2: Shibuya | H2: Shibuya Crossing | I2: 渋谷スクランブル交差点 | J2: Shibuya Crossing | K2: 🏙️ Ciudad y barrios | L2: cruce urbano | M2: A | N2: Icono urbano único, pero la experiencia es breve y muy saturada. | O2: Cruce peatonal masivo rodeado de pantallas y flujo humano. | P2: El movimiento colectivo, más que un monumento, es la atracción. | Q2: Cruce peatonal masivo rodeado de pantallas y flujo humano. | R2: 20–40 min | S2: Noche | T2: Todo el año | U2: Extremo | V2: Extremo | W2: 0 | X2: 0 | Y2: =W2*'Configuración'!$B$4 | Z2: =X2*'Configuración'!$B$4 | AA2: No | AB2: — | AC2: Espacio público 24 h | AD2: Sin cierre | AE2: JR/Metro Shibuya; salida Hachikō | AF2: Buena en áreas principales; confirmar detalles con el recinto | AG2: 35.6595 | AH2: 139.7005 | AI2: https://www.gotokyo.org/en/index.html | AJ2: Cambiante | AK2: MUST SEE | AL2: pareja, fotografía, ciudad, noche | AM2: 5 | AN2: 3 | AO2: 4 | AP2: 5 | AQ2: Imagen ideal: el movimiento colectivo, más que un monumento, es la atracción. con luz de noche, sin multitudes dominando el encuadre. | AR2: SHIBUYA SKY (~3 min a pie) | Shibuya PARCO + Nintendo TOKYO (~4 min a pie) | Cat Street (~14 min a pie) | AS2: Popular / turístico | AU2: https://www.google.com/maps/search/?api=1&query=Shibuya%20Crossing%2C%20Shibuya%2C%20Japan | AV2: 2026-09-01 | AW2: CALENDARIO / CONDICIÓN PENDIENTE | AX2: No hay cierre específico confirmado para la ventana, pero horarios o acceso pueden variar. | AY2: Reconfirmar en la web oficial al fijar fechas.
A3: JP-002 | B3: Tokio | C3: Kanto | D3: Tokio | E3: Shibuya | F3: Shibuya | G3: Shibuya | H3: SHIBUYA SKY | I3: 渋谷スカイ | J3: SHIBUYA SKY | K3: 🌅 Miradores | L3: mirador | M3: A | N3: La vista abierta y la posición sobre Shibuya justifican reservarlo. Clasificación v2: excelente y muy recomendable, pero no justifica por sí sola adaptar la ruta. | O3: Observatorio interior y azotea a 229 m sobre el cruce. | P3: La cubierta al aire libre produce una sensación más intensa que otros miradores. | Q3: Observatorio interior y azotea a 229 m sobre el cruce. | R3: 1–2 h | S3: Atardecer | T3: Todo el año; mejor visibilidad en invierno | U3: Extremo | V3: Extremo | W3: 2200 | X3: 3400 | Y3: =W3*'Configuración'!$B$4 | Z3: =X3*'Configuración'!$B$4 | AA3: Sí | AB3: 2–4 semanas; atardecer antes | AC3: Variable por fecha | AD3: Cierres meteorológicos de azotea | AE3: JR/Metro Shibuya, acceso directo | AF3: Buena en áreas principales; confirmar detalles con el recinto | AG3: 35.6585 | AH3: 139.7022 | AI3: https://www.shibuya-scramble-square.com/sky/ticket/en/ | AJ3: Cambiante | AK3: MUST SEE | AL3: pareja, fotografía, arquitectura, noche | AM3: 5 | AN3: 4 | AO3: 4 | AP3: 5 | AQ3: Imagen ideal: la cubierta al aire libre produce una sensación más intensa que otros miradores. con luz de atardecer, sin multitudes dominando el encuadre. | AR3: Shibuya Crossing (~3 min a pie) | Shibuya PARCO + Nintendo TOKYO (~7 min a pie) | Cat Street (~13 min a pie) | AS3: Popular / turístico | AU3: https://www.google.com/maps/search/?api=1&query=SHIBUYA%20SKY%2C%20Shibuya%2C%20Japan | AV3: 2026-09-01 | AW3: CALENDARIO / CONDICIÓN PENDIENTE | AX3: No hay cierre específico confirmado para la ventana, pero horarios o acceso pueden variar. | AY3: Reconfirmar en la web oficial al fijar fechas.
A4: JP-003 | B4: Tokio | C4: Kanto | D4: Tokio | E4: Shibuya | F4: Harajuku | G4: Harajuku–Meiji | H4: Meiji Jingu | I4: 明治神宮 | J4: Meiji Jingu | K4: ⛩️ Templos y santuarios | L4: santuario | M4: A | N4: El bosque y la escala ceremonial ofrecen un contraste esencial con Tokio. Clasificación v2: excelente y muy recomendable, pero no justifica por sí sola adaptar la ruta. | O4: Gran santuario sintoísta dentro de un bosque urbano denso. | P4: La transición inmediata del ruido de Harajuku al silencio forestal. | Q4: Gran santuario sintoísta dentro de un bosque urbano denso. | R4: 1–2 h | S4: Mañana | T4: Todo el año | U4: Alto | V4: Alto | W4: 0 | X4: 0 | Y4: =W4*'Configuración'!$B$4 | Z4: =X4*'Configuración'!$B$4 | AA4: No | AB4: — | AC4: Amanecer–atardecer; varía por mes | AD4: Sin cierre ordinario | AE4: JR Harajuku / Metro Meiji-jingumae | AF4: Parcial; pueden existir escalones, grava o edificios sin elevador | AG4: 35.6764 | AH4: 139.6993 | AI4: https://www.meijijingu.or.jp/en/ | AJ4: Cambiante | AK4: MUST SEE | AL4: pareja, cultura, naturaleza, fotografía | AM4: 4 | AN4: 4 | AO4: 5 | AP4: 4 | AQ4: Imagen ideal: la transición inmediata del ruido de harajuku al silencio forestal. con luz de mañana, sin multitudes dominando el encuadre. | AR4: Takeshita Street (~9 min a pie) | Ota Memorial Museum of Art (~12 min a pie) | Shinjuku Gyoen National Garden (~19 min a pie) | AS4: Popular / turístico | AU4: https://www.google.com/maps/search/?api=1&query=Meiji%20Jingu%2C%20Shibuya%2C%20Japan | AV4: 2026-09-01 | AW4: CALENDARIO / CONDICIÓN PENDIENTE | AX4: No hay cierre específico confirmado para la ventana, pero horarios o acceso pueden variar. | AY4: Reconfirmar en la web oficial al fijar fechas.
A5: JP-004 | B5: Tokio | C5: Kanto | D5: Tokio | E5: Shibuya | F5: Harajuku | G5: Harajuku–Meiji | H5: Takeshita Street | I5: 竹下通り | J5: Takeshita Street | K5: 🛍️ Compras | L5: calle comercial | M5: C | N5: Es famosa, pero las multitudes y tiendas repetitivas reducen el valor. | O5: Eje juvenil de moda, dulces y souvenirs. | P5: Concentra la estética kawaii más comercial en pocos cientos de metros. | Q5: Eje juvenil de moda, dulces y souvenirs. | R5: 30–60 min | S5: Mañana | T5: Todo el año | U5: Extremo | V5: Extremo | W5: 0 | X5: 0 | Y5: =W5*'Configuración'!$B$4 | Z5: =X5*'Configuración'!$B$4 | AA5: No | AB5: — | AC5: Tiendas aprox. 10:00–20:00 | AD5: Según comercio | AE5: JR Harajuku, salida Takeshita | AF5: Buena en áreas principales; confirmar detalles con el recinto | AG5: 35.6715 | AH5: 139.703 | AI5: https://www.gotokyo.org/en/index.html | AJ5: Cambiante | AK5: VIRAL / OPTIONAL | AL5: compras, cultura pop, fotografía | AM5: 4 | AN5: 2 | AO5: 2 | AP5: 5 | AQ5: Imagen ideal: concentra la estética kawaii más comercial en pocos cientos de metros. con luz de mañana, sin multitudes dominando el encuadre. | AR5: Ota Memorial Museum of Art (~3 min a pie) | Meiji Jingu (~9 min a pie) | Cat Street (~12 min a pie) | AS5: Alternativa menos saturada | AT5: Cat Street / Koenji | AU5: https://www.google.com/maps/search/?api=1&query=Takeshita%20Street%2C%20Shibuya%2C%20Japan | AV5: 2026-09-01 | AW5: CALENDARIO / CONDICIÓN PENDIENTE | AX5: No hay cierre específico confirmado para la ventana, pero horarios o acceso pueden variar. | AY5: Reconfirmar en la web oficial al fijar fechas.
A6: JP-005 | B6: Tokio | C6: Kanto | D6: Tokio | E6: Shibuya | F6: Jingumae | G6: Harajuku–Meiji | H6: Cat Street | I6: キャットストリート | J6: Cat Street | K6: 🏙️ Ciudad y barrios | L6: calle/barrio | M6: A | N6: Mejor paseo de moda urbana que Takeshita si se busca diseño y ambiente. | O6: Calle peatonal y callejones entre Harajuku y Shibuya. | P6: Boutiques, arquitectura y cafés con menos teatralidad turística. | Q6: Calle peatonal y callejones entre Harajuku y Shibuya. | R6: 1–2 h | S6: Tarde | T6: Todo el año | U6: Alto | V6: Medio | W6: 0 | X6: 0 | Y6: =W6*'Configuración'!$B$4 | Z6: =X6*'Configuración'!$B$4 | AA6: No | AB6: — | AC6: Espacio público; comercios variables | AD6: Sin cierre | AE6: Metro Meiji-jingumae / Shibuya | AF6: Buena en áreas principales; confirmar detalles con el recinto | AG6: 35.6652 | AH6: 139.7088 | AI6: https://www.gotokyo.org/en/index.html | AJ6: Cambiante | AK6: ALTERNATIVE | AL6: pareja, diseño, compras, fotografía | AM6: 4 | AN6: 4 | AO6: 5 | AP6: 3 | AQ6: Imagen ideal: boutiques, arquitectura y cafés con menos teatralidad turística. con luz de tarde, sin multitudes dominando el encuadre. | AR6: Ota Memorial Museum of Art (~10 min a pie) | Nezu Museum (~11 min a pie) | Takeshita Street (~12 min a pie) | AS6: Alternativa menos saturada | AT6: Takeshita Street | AU6: https://www.google.com/maps/search/?api=1&query=Cat%20Street%2C%20Shibuya%2C%20Japan | AV6: 2026-09-01 | AW6: CALENDARIO / CONDICIÓN PENDIENTE | AX6: No hay cierre específico confirmado para la ventana, pero horarios o acceso pueden variar. | AY6: Reconfirmar en la web oficial al fijar fechas.
A7: JP-006 | B7: Tokio | C7: Kanto | D7: Tokio | E7: Minato | F7: Aoyama | G7: Aoyama–Omotesando | H7: Nezu Museum | I7: 根津美術館 | J7: Nezu Museum | K7: 🎨 Arte | L7: museo y jardín | M7: A | N7: Colección refinada y uno de los jardines museísticos más bellos de la ciudad. | O7: Arte japonés y asiático en un edificio de Kengo Kuma con jardín privado. | P7: Une arquitectura contemporánea, antigüedades y paisaje en una visita compacta. | Q7: Arte japonés y asiático en un edificio de Kengo Kuma con jardín privado. | R7: 1.5–2.5 h | S7: Mañana | T7: Primavera y otoño | U7: Medio | V7: Medio | W7: 1500 | X7: 1800 | Y7: =W7*'Configuración'!$B$4 | Z7: =X7*'Configuración'!$B$4 | AA7: Recomendable | AB7: Días o semanas para exposición popular | AC7: 10:00–17:00 aprox.; verificar exposición | AD7: Lunes y montaje; verificar | AE7: Metro Omote-sando, 8–10 min a pie | AF7: Parcial; pueden existir escalones, grava o edificios sin elevador | AG7: 35.6622 | AH7: 139.7171 | AI7: https://www.nezu-muse.or.jp/en/ | AJ7: Cambiante | AK7: ART / GARDEN | AL7: pareja, arte, arquitectura, jardines | AM7: 5 | AN7: 5 | AO7: 5 | AP7: 2 | AQ7: Imagen ideal: une arquitectura contemporánea, antigüedades y paisaje en una visita compacta. con luz de mañana, sin multitudes dominando el encuadre. | AR7: Cat Street (~11 min a pie) | The National Art Center, Tokyo (~13 min a pie) | Mori Art Museum + Tokyo City View (~16 min a pie) | AS7: Semi-hidden | AU7: https://www.google.com/maps/search/?api=1&query=Nezu%20Museum%2C%20Minato%2C%20Japan | AV7: 2026-09-01 | AW7: CALENDARIO / CONDICIÓN PENDIENTE | AX7: No hay cierre específico confirmado para la ventana, pero horarios o acceso pueden variar. | AY7: Reconfirmar en la web oficial al fijar fechas.
A8: JP-007 | B8: Tokio | C8: Kanto | D8: Tokio | E8: Shibuya | F8: Harajuku | G8: Harajuku–Meiji | H8: Ota Memorial Museum of Art | I8: 太田記念美術館 | J8: Ota Memorial Museum of Art | K8: 🎨 Arte | L8: museo | M8: A | N8: Pequeño, especializado y excelente para comprender el ukiyo-e sin invertir medio día. | O8: Museo íntimo dedicado a grabados ukiyo-e con exposiciones rotativas. | P8: Especialización y escala humana junto al caos de Harajuku. | Q8: Museo íntimo dedicado a grabados ukiyo-e con exposiciones rotativas. | R8: 45–75 min | S8: Tarde | T8: Todo el año | U8: Bajo | V8: Bajo | W8: 1000 | X8: 1400 | Y8: =W8*'Configuración'!$B$4 | Z8: =X8*'Configuración'!$B$4 | AA8: No | AB8: — | AC8: 10:30–17:30 aprox.; verificar muestra | AD8: Cierres entre exposiciones | AE8: Metro Meiji-jingumae | AF8: Buena en áreas principales; confirmar detalles con el recinto | AG8: 35.6708 | AH8: 139.7054 | AI8: http://www.ukiyoe-ota-muse.jp/eng | AJ8: Cambiante | AK8: HIDDEN GEM | AL8: arte, cultura, lluvia | AM8: 3 | AN8: 5 | AO8: 5 | AP8: 1 | AQ8: Imagen ideal: especialización y escala humana junto al caos de harajuku. con luz de tarde, sin multitudes dominando el encuadre. | AR8: Takeshita Street (~3 min a pie) | Cat Street (~10 min a pie) | Meiji Jingu (~12 min a pie) | AS8: Hidden Gem real | AU8: https://www.google.com/maps/search/?api=1&query=Ota%20Memorial%20Museum%20of%20Art%2C%20Shibuya%2C%20Japan | AV8: 2026-09-01 | AW8: CALENDARIO / CONDICIÓN PENDIENTE | AX8: No hay cierre específico confirmado para la ventana, pero horarios o acceso pueden variar. | AY8: Reconfirmar en la web oficial al fijar fechas.
A9: JP-008 | B9: Tokio | C9: Kanto | D9: Tokio | E9: Shibuya | F9: Shibuya | G9: Shibuya | H9: Shibuya PARCO + Nintendo TOKYO | I9: 渋谷PARCO・Nintendo TOKYO | J9: Shibuya PARCO + Nintendo TOKYO | K9: 🎮 Videojuegos | L9: centro de cultura pop | M9: A | N9: Concentra Nintendo, Pokémon, Capcom y diseño en un solo edificio. | O9: Complejo comercial con tiendas oficiales y cultura pop japonesa. | P9: Es el nodo más eficiente para varias franquicias sin desplazamientos. | Q9: Complejo comercial con tiendas oficiales y cultura pop japonesa. | R9: 1.5–3 h | S9: Tarde | T9: Todo el año | U9: Extremo | V9: Alto | W9: 0 | X9: 0 | Y9: =W9*'Configuración'!$B$4 | Z9: =X9*'Configuración'!$B$4 | AA9: No | AB9: — | AC9: Aprox. 11:00–21:00; verificar | AD9: Según edificio | AE9: JR/Metro Shibuya | AF9: Buena en áreas principales; confirmar detalles con el recinto | AG9: 35.662 | AH9: 139.6988 | AI9: https://shibuya.parco.jp.e.aiv.hp.transer.com/ | AJ9: Cambiante | AK9: GAMING | AL9: videojuegos, anime, compras | AM9: 4 | AN9: 4 | AO9: 4 | AP9: 5 | AQ9: Imagen ideal: es el nodo más eficiente para varias franquicias sin desplazamientos. con luz de tarde, sin multitudes dominando el encuadre. | AR9: Shibuya Crossing (~4 min a pie) | SHIBUYA SKY (~7 min a pie) | Cat Street (~14 min a pie) | AS9: Popular / turístico | AU9: https://www.google.com/maps/search/?api=1&query=Shibuya%20PARCO%20%2B%20Nintendo%20TOKYO%2C%20Shibuya%2C%20Japan | AV9: 2026-09-01 | AW9: CALENDARIO / CONDICIÓN PENDIENTE | AX9: No hay cierre específico confirmado para la ventana, pero horarios o acceso pueden variar. | AY9: Reconfirmar en la web oficial al fijar fechas.
A10: JP-009 | B10: Tokio | C10: Kanto | D10: Tokio | E10: Shibuya | F10: Daikanyama | G10: Daikanyama–Ebisu | H10: Daikanyama T-SITE | I10: 代官山T-SITE | J10: Daikanyama T-SITE | K10: 🧩 Extraño/peculiar/único | L10: librería/arquitectura | M10: A | N10: Gran pausa de diseño, libros y café fuera de los circuitos más ruidosos. | O10: Conjunto de librerías y pabellones de arquitectura contemporánea. | P10: La experiencia de curaduría y espacio importa tanto como comprar. | Q10: Conjunto de librerías y pabellones de arquitectura contemporánea. | R10: 1–2 h | S10: Tarde | T10: Todo el año | U10: Medio | V10: Bajo | W10: 0 | X10: 0 | Y10: =W10*'Configuración'!$B$4 | Z10: =X10*'Configuración'!$B$4 | AA10: No | AB10: — | AC10: Aprox. 07:00–23:00; comercios varían | AD10: Sin cierre ordinario | AE10: Tokyu Daikanyama, 5 min | AF10: Buena en áreas principales; confirmar detalles con el recinto | AG10: 35.6488 | AH10: 139.6997 | AI10: https://store.tsite.jp/daikanyama/english/ | AJ10: Cambiante | AK10: HIDDEN GEM | AL10: pareja, diseño, libros, café | AM10: 4 | AN10: 5 | AO10: 5 | AP10: 2 | AQ10: Imagen ideal: la experiencia de curaduría y espacio importa tanto como comprar. con luz de tarde, sin multitudes dominando el encuadre. | AR10: SHIBUYA SKY (~15 min a pie) | Shibuya Crossing (~17 min a pie) | Shibuya PARCO + Nintendo TOKYO (~21 min a pie) | AS10: Semi-hidden | AU10: https://www.google.com/maps/search/?api=1&query=Daikanyama%20T-SITE%2C%20Shibuya%2C%20Japan | AV10: 2026-09-01 | AW10: CALENDARIO / CONDICIÓN PENDIENTE | AX10: No hay cierre específico confirmado para la ventana, pero horarios o acceso pueden variar. | AY10: Reconfirmar en la web oficial al fijar fechas.
A11: JP-010 | B11: Tokio | C11: Kanto | D11: Tokio | E11: Shinjuku | F11: Shinjuku | G11: Shinjuku | H11: Shinjuku Gyoen National Garden | I11: 新宿御苑 | J11: Shinjuku Gyoen National Garden | K11: 🌸 Jardines y paisajes | L11: jardín | M11: A | N11: El mejor gran jardín central para entender la escala y el contraste de Tokio. Clasificación v2: excelente y muy recomendable, pero no justifica por sí sola adaptar la ruta. | O11: Jardines japonés, inglés y francés bajo el skyline de Shinjuku. | P11: Combina paisaje formal y rascacielos con espacio suficiente para descansar. | Q11: Jardines japonés, inglés y francés bajo el skyline de Shinjuku. | R11: 2–3 h | S11: Mañana | T11: Sakura y otoño; bueno todo el año | U11: Alto | V11: Alto | W11: 500 | X11: 500 | Y11: =W11*'Configuración'!$B$4 | Z11: =X11*'Configuración'!$B$4 | AA11: No | AB11: — | AC11: 09:00–16:00/17:30 según temporada | AD11: Lunes y fechas especiales; verificar | AE11: Shinjuku-gyoemmae / Sendagaya | AF11: Parcial; pueden existir escalones, grava o edificios sin elevador | AG11: 35.6852 | AH11: 139.7101 | AI11: https://fng.or.jp/shinjuku/en/ | AJ11: Cambiante | AK11: MUST SEE | AL11: pareja, naturaleza, fotografía, descanso | AM11: 5 | AN11: 4 | AO11: 5 | AP11: 4 | AQ11: Imagen ideal: combina paisaje formal y rascacielos con espacio suficiente para descansar. con luz de mañana, sin multitudes dominando el encuadre. | AR11: Golden Gai (~15 min a pie) | Kabukicho (~17 min a pie) | Omoide Yokocho (~18 min a pie) | AS11: Popular / turístico | AU11: https://www.google.com/maps/search/?api=1&query=Shinjuku%20Gyoen%20National%20Garden%2C%20Shinjuku%2C%20Japan | AV11: 2026-09-01 | AW11: ABIERTO; FLORACIÓN NO GARANTIZADA | AX11: En Japón central la floración plena suele ser más tardía; finales de marzo es incierto. | AY11: No basar la visita en sakura hasta el pronóstico 2027.
A12: JP-011 | B12: Tokio | C12: Kanto | D12: Tokio | E12: Shinjuku | F12: Nishi-Shinjuku | G12: Shinjuku | H12: Tokyo Metropolitan Government Observatory | I12: 東京都庁展望室 | J12: Tokyo Metropolitan Government Observatory | K12: 🌅 Miradores | L12: mirador | M12: A | N12: La mejor vista gratuita de la ciudad y excelente respaldo si otros miradores se agotan. | O12: Observatorios gratuitos en las torres del gobierno metropolitano. | P12: Costo cero, vista amplia y proyección mapping nocturno cercana. | Q12: Observatorios gratuitos en las torres del gobierno metropolitano. | R12: 45–90 min | S12: Atardecer | T12: Invierno para Fuji | U12: Alto | V12: Medio | W12: 0 | X12: 0 | Y12: =W12*'Configuración'!$B$4 | Z12: =X12*'Configuración'!$B$4 | AA12: No | AB12: — | AC12: Variable; comprobar torre abierta | AD12: Cierres variables | AE12: Tochomae, acceso subterráneo | AF12: Buena en áreas principales; confirmar detalles con el recinto | AG12: 35.6896 | AH12: 139.6921 | AI12: https://www.yokoso.metro.tokyo.lg.jp/en/tenbou/ | AJ12: Cambiante | AK12: VALUE | AL12: fotografía, arquitectura, presupuesto | AM12: 4 | AN12: 3 | AO12: 5 | AP12: 3 | AQ12: Imagen ideal: costo cero, vista amplia y proyección mapping nocturno cercana. con luz de atardecer, sin multitudes dominando el encuadre. | AR12: Omoide Yokocho (~11 min a pie) | Kabukicho (~15 min a pie) | Golden Gai (~18 min a pie) | AS12: Alternativa menos saturada | AT12: SHIBUYA SKY | AU12: https://www.google.com/maps/search/?api=1&query=Tokyo%20Metropolitan%20Government%20Observatory%2C%20Shinjuku%2C%20Japan | AV12: 2026-09-01 | AW12: CALENDARIO / CONDICIÓN PENDIENTE | AX12: No hay cierre específico confirmado para la ventana, pero horarios o acceso pueden variar. | AY12: Reconfirmar en la web oficial al fijar fechas.
A13: JP-012 | B13: Tokio | C13: Kanto | D13: Tokio | E13: Shinjuku | F13: Kabukicho | G13: Shinjuku | H13: Kabukicho | I13: 歌舞伎町 | J13: Kabukicho | K13: 🌃 Nocturno | L13: barrio nocturno | M13: B | N13: Visualmente potente, pero conviene por ambiente y fotografía, no por atracciones concretas. | O13: Distrito de neón, ocio, cines, bares y enorme densidad peatonal. | P13: Es el Tokio nocturno más teatral y caótico. | Q13: Distrito de neón, ocio, cines, bares y enorme densidad peatonal. | R13: 1–2 h | S13: Noche | T13: Todo el año | U13: Extremo | V13: Extremo | W13: 0 | X13: 0 | Y13: =W13*'Configuración'!$B$4 | Z13: =X13*'Configuración'!$B$4 | AA13: No | AB13: — | AC13: Espacio público 24 h | AD13: Sin cierre | AE13: JR/Metro Shinjuku / Seibu-Shinjuku | AF13: Buena en áreas principales; confirmar detalles con el recinto | AG13: 35.6944 | AH13: 139.7028 | AI13: https://www.gotokyo.org/en/index.html | AJ13: Cambiante | AK13: NIGHT | AL13: pareja, fotografía, noche | AM13: 5 | AN13: 3 | AO13: 3 | AP13: 5 | AQ13: Imagen ideal: es el tokio nocturno más teatral y caótico. con luz de noche, sin multitudes dominando el encuadre. | AR13: Golden Gai (~3 min a pie) | Omoide Yokocho (~5 min a pie) | Tokyo Metropolitan Government Observatory (~15 min a pie) | AS13: Popular / turístico | AU13: https://www.google.com/maps/search/?api=1&query=Kabukicho%2C%20Shinjuku%2C%20Japan | AV13: 2026-09-01 | AW13: CALENDARIO / CONDICIÓN PENDIENTE | AX13: No hay cierre específico confirmado para la ventana, pero horarios o acceso pueden variar. | AY13: Reconfirmar en la web oficial al fijar fechas.
A14: JP-013 | B14: Tokio | C14: Kanto | D14: Tokio | E14: Shinjuku | F14: Kabukicho | G14: Shinjuku | H14: Golden Gai | I14: 新宿ゴールデン街 | J14: Golden Gai | K14: 🌃 Nocturno | L14: microbarrio de bares | M14: A | N14: Conserva una escala diminuta y un paisaje nocturno irrepetible. | O14: Red de callejones con cientos de bares minúsculos. | P14: La arquitectura apretada y el trato de barra no se replican en un distrito moderno. | Q14: Red de callejones con cientos de bares minúsculos. | R14: 1.5–3 h | S14: Noche | T14: Todo el año | U14: Alto | V14: Alto | W14: 1000 | X14: 5000 | Y14: =W14*'Configuración'!$B$4 | Z14: =X14*'Configuración'!$B$4 | AA14: Recomendable | AB14: Mismo día o pocos días en bares populares | AC14: Desde tarde hasta madrugada | AD14: Según bar | AE14: Shinjuku-sanchome / Seibu-Shinjuku | AF14: Buena en áreas principales; confirmar detalles con el recinto | AG14: 35.6941 | AH14: 139.7048 | AI14: https://www.gotokyo.org/en/index.html | AJ14: Cambiante | AK14: NIGHT | AL14: pareja, noche, fotografía, cultura local | AM14: 5 | AN14: 5 | AO14: 4 | AP14: 4 | AQ14: Imagen ideal: la arquitectura apretada y el trato de barra no se replican en un distrito moderno. con luz de noche, sin multitudes dominando el encuadre. | AR14: Kabukicho (~3 min a pie) | Omoide Yokocho (~7 min a pie) | Shinjuku Gyoen National Garden (~15 min a pie) | AS14: Popular / turístico | AU14: https://www.google.com/maps/search/?api=1&query=Golden%20Gai%2C%20Shinjuku%2C%20Japan | AV14: 2026-09-01 | AW14: CALENDARIO / CONDICIÓN PENDIENTE | AX14: No hay cierre específico confirmado para la ventana, pero horarios o acceso pueden variar. | AY14: Reconfirmar en la web oficial al fijar fechas.
A15: JP-014 | B15: Tokio | C15: Kanto | D15: Tokio | E15: Shinjuku | F15: Nishi-Shinjuku | G15: Shinjuku | H15: Omoide Yokocho | I15: 思い出横丁 | J15: Omoide Yokocho | K15: 🍜 Gastronomía | L15: callejón gastronómico | M15: B | N15: Atmosférico y cómodo, aunque hoy es muy turístico y pequeño. | O15: Callejones de yakitori y tabernas junto a las vías. | P15: Humo, escala y densidad visual de posguerra en pleno Shinjuku. | Q15: Callejones de yakitori y tabernas junto a las vías. | R15: 45–90 min | S15: Noche | T15: Todo el año | U15: Extremo | V15: Extremo | W15: 1500 | X15: 5000 | Y15: =W15*'Configuración'!$B$4 | Z15: =X15*'Configuración'!$B$4 | AA15: No | AB15: — | AC15: Según local, tarde–noche | AD15: Según local | AE15: JR Shinjuku, salida oeste | AF15: Buena en áreas principales; confirmar detalles con el recinto | AG15: 35.6929 | AH15: 139.6996 | AI15: https://www.gotokyo.org/en/index.html | AJ15: Cambiante | AK15: FOOD / NIGHT | AL15: comida, noche, fotografía | AM15: 5 | AN15: 3 | AO15: 3 | AP15: 5 | AQ15: Imagen ideal: humo, escala y densidad visual de posguerra en pleno shinjuku. con luz de noche, sin multitudes dominando el encuadre. | AR15: Kabukicho (~5 min a pie) | Golden Gai (~7 min a pie) | Tokyo Metropolitan Government Observatory (~11 min a pie) | AS15: Popular / turístico | AU15: https://www.google.com/maps/search/?api=1&query=Omoide%20Yokocho%2C%20Shinjuku%2C%20Japan | AV15: 2026-09-01 | AW15: CALENDARIO / CONDICIÓN PENDIENTE | AX15: No hay cierre específico confirmado para la ventana, pero horarios o acceso pueden variar. | AY15: Reconfirmar en la web oficial al fijar fechas.
A16: JP-015 | B16: Tokio | C16: Kanto | D16: Tokio | E16: Shinjuku | F16: Kagurazaka | G16: Kagurazaka | H16: Kagurazaka backstreets | I16: 神楽坂 | J16: Kagurazaka backstreets | K16: 🏙️ Ciudad y barrios | L16: barrio | M16: A | N16: Alternativa elegante y menos obvia a los barrios tradicionales más saturados. | O16: Pendiente principal y callejones de piedra con restaurantes y antiguas casas de geisha. | P16: Mezcla herencia japonesa, influencia francesa y vida residencial. | Q16: Pendiente principal y callejones de piedra con restaurantes y antiguas casas de geisha. | R16: 2–3 h | S16: Tarde | T16: Todo el año | U16: Medio | V16: Bajo | W16: 0 | X16: 0 | Y16: =W16*'Configuración'!$B$4 | Z16: =X16*'Configuración'!$B$4 | AA16: No | AB16: — | AC16: Espacio público; negocios variables | AD16: Sin cierre | AE16: Iidabashi / Kagurazaka | AF16: Buena en áreas principales; confirmar detalles con el recinto | AG16: 35.7016 | AH16: 139.7403 | AI16: https://www.gotokyo.org/en/index.html | AJ16: Cambiante | AK16: HIDDEN GEM | AL16: pareja, comida, arquitectura, noche | AM16: 4 | AN16: 5 | AO16: 5 | AP16: 2 | AQ16: Imagen ideal: mezcla herencia japonesa, influencia francesa y vida residencial. con luz de tarde, sin multitudes dominando el encuadre. | AR16: Jimbocho Book Town (~24 min a pie) | Imperial Palace East Gardens (~30 min en transporte) | Kanda Myojin (~35 min en transporte) | AS16: Semi-hidden | AU16: https://www.google.com/maps/search/?api=1&query=Kagurazaka%20backstreets%2C%20Shinjuku%2C%20Japan | AV16: 2026-09-01 | AW16: CALENDARIO / CONDICIÓN PENDIENTE | AX16: No hay cierre específico confirmado para la ventana, pero horarios o acceso pueden variar. | AY16: Reconfirmar en la web oficial al fijar fechas.
A17: JP-016 | B17: Tokio | C17: Kanto | D17: Tokio | E17: Taito | F17: Asakusa | G17: Asakusa | H17: Sensō-ji | I17: 浅草寺 | J17: Sensō-ji | K17: ⛩️ Templos y santuarios | L17: templo | M17: A | N17: Icono histórico con escala, rituales y vida de barrio que justifican la multitud. Clasificación v2: excelente y muy recomendable, pero no justifica por sí sola adaptar la ruta. | O17: El templo budista más antiguo de Tokio, con Kaminarimon y gran recinto. | P17: La experiencia cambia radicalmente antes de abrir comercios y por la noche. | Q17: El templo budista más antiguo de Tokio, con Kaminarimon y gran recinto. | R17: 1–2 h | S17: Mañana | T17: Todo el año | U17: Extremo | V17: Extremo | W17: 0 | X17: 0 | Y17: =W17*'Configuración'!$B$4 | Z17: =X17*'Configuración'!$B$4 | AA17: No | AB17: — | AC17: Recinto exterior 24 h; salón aprox. 06:00–17:00 | AD17: Sin cierre ordinario | AE17: Metro Asakusa | AF17: Parcial; pueden existir escalones, grava o edificios sin elevador | AG17: 35.7148 | AH17: 139.7967 | AI17: https://www.senso-ji.jp/english/ | AJ17: Cambiante | AK17: MUST SEE | AL17: cultura, fotografía, historia | AM17: 5 | AN17: 4 | AO17: 5 | AP17: 5 | AQ17: Imagen ideal: la experiencia cambia radicalmente antes de abrir comercios y por la noche. con luz de mañana, sin multitudes dominando el encuadre. | AR17: Asakusa Culture Tourist Information Center (~6 min a pie) | Kappabashi Kitchen Town (~10 min a pie) | Tokyo Skytree (~19 min a pie) | AS17: Popular / turístico | AU17: https://www.google.com/maps/search/?api=1&query=Sens%C5%8D-ji%2C%20Taito%2C%20Japan | AV17: 2026-09-01 | AW17: CALENDARIO / CONDICIÓN PENDIENTE | AX17: No hay cierre específico confirmado para la ventana, pero horarios o acceso pueden variar. | AY17: Reconfirmar en la web oficial al fijar fechas.
A18: JP-017 | B18: Tokio | C18: Kanto | D18: Tokio | E18: Taito | F18: Asakusa | G18: Asakusa | H18: Asakusa Culture Tourist Information Center | I18: 浅草文化観光センター | J18: Asakusa Culture Tourist Information Center | K18: 🌅 Miradores | L18: centro/mirador | M18: A | N18: Vista gratuita y perfectamente situada sobre Kaminarimon y Nakamise. | O18: Centro de información de Kengo Kuma con terraza panorámica. | P18: Permite leer la geometría de Asakusa sin pagar observatorio. | Q18: Centro de información de Kengo Kuma con terraza panorámica. | R18: 20–45 min | S18: Atardecer | T18: Todo el año | U18: Medio | V18: Medio | W18: 0 | X18: 0 | Y18: =W18*'Configuración'!$B$4 | Z18: =X18*'Configuración'!$B$4 | AA18: No | AB18: — | AC18: Aprox. 09:00–20:00 | AD18: Sin cierre ordinario | AE18: Metro Asakusa, frente a Kaminarimon | AF18: Buena en áreas principales; confirmar detalles con el recinto | AG18: 35.7107 | AH18: 139.7966 | AI18: https://www.city.taito.lg.jp/bunka_kanko/kankoinfo/info/oyakudachi/kankocenter/a-tic-gaiyo.html | AJ18: Cambiante | AK18: VALUE | AL18: arquitectura, fotografía, presupuesto | AM18: 4 | AN18: 4 | AO18: 5 | AP18: 2 | AQ18: Imagen ideal: permite leer la geometría de asakusa sin pagar observatorio. con luz de atardecer, sin multitudes dominando el encuadre. | AR18: Sensō-ji (~6 min a pie) | Kappabashi Kitchen Town (~13 min a pie) | Tokyo Skytree (~18 min a pie) | AS18: Hidden Gem real | AU18: https://www.google.com/maps/search/?api=1&query=Asakusa%20Culture%20Tourist%20Information%20Center%2C%20Taito%2C%20Japan | AV18: 2026-09-01 | AW18: CALENDARIO / CONDICIÓN PENDIENTE | AX18: No hay cierre específico confirmado para la ventana, pero horarios o acceso pueden variar. | AY18: Reconfirmar en la web oficial al fijar fechas.
A19: JP-018 | B19: Tokio | C19: Kanto | D19: Tokio | E19: Taito | F19: Kappabashi | G19: Asakusa | H19: Kappabashi Kitchen Town | I19: かっぱ橋道具街 | J19: Kappabashi Kitchen Town | K19: 🛍️ Compras | L19: calle comercial especializada | M19: A | N19: Especialización real y objetos japoneses útiles, no solo recuerdos genéricos. | O19: Distrito de cuchillos, cerámica, utensilios y comida de plástico. | P19: Muestra la infraestructura de la gastronomía japonesa. | Q19: Distrito de cuchillos, cerámica, utensilios y comida de plástico. | R19: 1.5–3 h | S19: Tarde | T19: Días laborables | U19: Medio | V19: Medio | W19: 0 | X19: 0 | Y19: =W19*'Configuración'!$B$4 | Z19: =X19*'Configuración'!$B$4 | AA19: No | AB19: — | AC19: Mayoría 09:00–17:00 | AD19: Muchos domingos/festivos | AE19: Tawaramachi / Asakusa | AF19: Buena en áreas principales; confirmar detalles con el recinto | AG19: 35.7157 | AH19: 139.7885 | AI19: https://www.kappabashi.or.jp/en/ | AJ19: Cambiante | AK19: HIDDEN GEM | AL19: comida, compras, diseño | AM19: 4 | AN19: 5 | AO19: 5 | AP19: 2 | AQ19: Imagen ideal: muestra la infraestructura de la gastronomía japonesa. con luz de tarde, sin multitudes dominando el encuadre. | AR19: Sensō-ji (~10 min a pie) | Asakusa Culture Tourist Information Center (~13 min a pie) | Tokyo National Museum (~16 min a pie) | AS19: Semi-hidden | AU19: https://www.google.com/maps/search/?api=1&query=Kappabashi%20Kitchen%20Town%2C%20Taito%2C%20Japan | AV19: 2026-09-01 | AW19: CALENDARIO / CONDICIÓN PENDIENTE | AX19: No hay cierre específico confirmado para la ventana, pero horarios o acceso pueden variar. | AY19: Reconfirmar en la web oficial al fijar fechas.
A20: JP-019 | B20: Tokio | C20: Kanto | D20: Tokio | E20: Sumida | F20: Oshiage | G20: Skytree–Sumida | H20: Tokyo Skytree | I20: 東京スカイツリー | J20: Tokyo Skytree | K20: 🌅 Miradores | L20: torre/mirador | M20: B | N20: La mayor altura y vistas lejanas compensan el entorno comercial, pero no es la más emocional. Clasificación v2: recomendable si encaja; su valor depende más de interés, saturación o logística. | O20: Torre de radiodifusión con dos observatorios a 350 y 450 m. | P20: Ningún otro mirador urbano del país alcanza su altura. | Q20: Torre de radiodifusión con dos observatorios a 350 y 450 m. | R20: 1.5–2.5 h | S20: Atardecer | T20: Invierno | U20: Extremo | V20: Extremo | W20: 2100 | X20: 3400 | Y20: =W20*'Configuración'!$B$4 | Z20: =X20*'Configuración'!$B$4 | AA20: Recomendable | AB20: 1–2 semanas | AC20: Variable por fecha | AD20: Sin cierre ordinario; clima | AE20: Oshiage / Tokyo Skytree | AF20: Buena en áreas principales; confirmar detalles con el recinto | AG20: 35.7101 | AH20: 139.8107 | AI20: https://www.tokyo-skytree.jp/en/ | AJ20: Cambiante | AK20: ICON | AL20: fotografía, arquitectura, altura | AM20: 5 | AN20: 4 | AO20: 3 | AP20: 5 | AQ20: Imagen ideal: ningún otro mirador urbano del país alcanza su altura. con luz de atardecer, sin multitudes dominando el encuadre. | AR20: Asakusa Culture Tourist Information Center (~18 min a pie) | Sensō-ji (~19 min a pie) | The Sumida Hokusai Museum (~25 min a pie) | AS20: Popular / turístico | AU20: https://www.google.com/maps/search/?api=1&query=Tokyo%20Skytree%2C%20Sumida%2C%20Japan | AV20: 2026-09-01 | AW20: CALENDARIO / CONDICIÓN PENDIENTE | AX20: No hay cierre específico confirmado para la ventana, pero horarios o acceso pueden variar. | AY20: Reconfirmar en la web oficial al fijar fechas.
A21: JP-020 | B21: Tokio | C21: Kanto | D21: Tokio | E21: Sumida | F21: Ryogoku | G21: Skytree–Sumida | H21: The Sumida Hokusai Museum | I21: すみだ北斎美術館 | J21: The Sumida Hokusai Museum | K21: 🎨 Arte | L21: museo | M21: A | N21: Museo especializado con gran arquitectura y relación directa con el barrio natal de Hokusai. | O21: Colección y exposiciones sobre Katsushika Hokusai. | P21: Contexto local y edificio de Kazuyo Sejima. | Q21: Colección y exposiciones sobre Katsushika Hokusai. | R21: 1–2 h | S21: Tarde | T21: Todo el año | U21: Bajo | V21: Bajo | W21: 400 | X21: 1500 | Y21: =W21*'Configuración'!$B$4 | Z21: =X21*'Configuración'!$B$4 | AA21: No | AB21: — | AC21: 09:30–17:30 aprox. | AD21: Lunes; verificar | AE21: JR/Toei Ryogoku | AF21: Buena en áreas principales; confirmar detalles con el recinto | AG21: 35.6963 | AH21: 139.8005 | AI21: https://hokusai-museum.jp/?lang=en | AJ21: Cambiante | AK21: HIDDEN GEM | AL21: arte, arquitectura, cultura | AM21: 4 | AN21: 5 | AO21: 5 | AP21: 1 | AQ21: Imagen ideal: contexto local y edificio de kazuyo sejima. con luz de tarde, sin multitudes dominando el encuadre. | AR21: Edo-Tokyo Museum (~5 min a pie) | Asakusa Culture Tourist Information Center (~23 min a pie) | Tokyo Skytree (~25 min a pie) | AS21: Hidden Gem real | AU21: https://www.google.com/maps/search/?api=1&query=The%20Sumida%20Hokusai%20Museum%2C%20Sumida%2C%20Japan | AV21: 2026-09-01 | AW21: CALENDARIO / CONDICIÓN PENDIENTE | AX21: No hay cierre específico confirmado para la ventana, pero horarios o acceso pueden variar. | AY21: Reconfirmar en la web oficial al fijar fechas.
A22: JP-021 | B22: Tokio | C22: Kanto | D22: Tokio | E22: Taito | F22: Ueno | G22: Ueno–Yanaka | H22: Tokyo National Museum | I22: 東京国立博物館 | J22: Tokyo National Museum | K22: 🏛️ Museos | L22: museo nacional | M22: S | N22: La mejor introducción concentrada al arte y patrimonio material japonés. | O22: El museo más antiguo de Japón con colecciones nacionales y asiáticas. | P22: Calidad y amplitud muy superiores a una visita rápida de templo en templo. | Q22: El museo más antiguo de Japón con colecciones nacionales y asiáticas. | R22: 3–5 h | S22: Mañana | T22: Todo el año | U22: Alto | V22: Alto | W22: 1000 | X22: 2200 | Y22: =W22*'Configuración'!$B$4 | Z22: =X22*'Configuración'!$B$4 | AA22: Recomendable | AB22: Días/semanas para exposiciones | AC22: 09:30–17:00 aprox. | AD22: Lunes; verificar | AE22: JR/Metro Ueno | AF22: Buena en áreas principales; confirmar detalles con el recinto | AG22: 35.7188 | AH22: 139.7765 | AI22: https://www.tnm.jp/?lang=en | AJ22: Cambiante | AK22: MUST SEE | AL22: historia, arte, cultura, lluvia | AM22: 4 | AN22: 5 | AO22: 5 | AP22: 4 | AQ22: Imagen ideal: calidad y amplitud muy superiores a una visita rápida de templo en templo. con luz de mañana, sin multitudes dominando el encuadre. | AR22: Ameyoko (~14 min a pie) | Kappabashi Kitchen Town (~16 min a pie) | Yanaka Ginza and cemetery lanes (~18 min a pie) | AS22: Popular / turístico | AU22: https://www.google.com/maps/search/?api=1&query=Tokyo%20National%20Museum%2C%20Taito%2C%20Japan | AV22: 2026-09-01 | AW22: CALENDARIO / CONDICIÓN PENDIENTE | AX22: No hay cierre específico confirmado para la ventana, pero horarios o acceso pueden variar. | AY22: Reconfirmar en la web oficial al fijar fechas.
A23: JP-022 | B23: Tokio | C23: Kanto | D23: Tokio | E23: Taito | F23: Ueno | G23: Ueno–Yanaka | H23: Ameyoko | I23: アメ横 | J23: Ameyoko | K23: 🛍️ Compras | L23: mercado/calle | M23: B | N23: Gran energía popular, aunque parte de la oferta es genérica y muy turística. | O23: Mercado callejero bajo y junto a las vías entre Ueno y Okachimachi. | P23: Mezcla alimentos, ropa, tiendas asiáticas y ruido urbano. | Q23: Mercado callejero bajo y junto a las vías entre Ueno y Okachimachi. | R23: 1–2 h | S23: Tarde | T23: Todo el año | U23: Extremo | V23: Alto | W23: 0 | X23: 0 | Y23: =W23*'Configuración'!$B$4 | Z23: =X23*'Configuración'!$B$4 | AA23: No | AB23: — | AC23: Según comercio | AD23: Según comercio | AE23: Ueno / Okachimachi | AF23: Buena en áreas principales; confirmar detalles con el recinto | AG23: 35.7102 | AH23: 139.7748 | AI23: https://www.gotokyo.org/en/index.html | AJ23: Cambiante | AK23: STREET | AL23: comida, compras, fotografía | AM23: 4 | AN23: 3 | AO23: 4 | AP23: 4 | AQ23: Imagen ideal: mezcla alimentos, ropa, tiendas asiáticas y ruido urbano. con luz de tarde, sin multitudes dominando el encuadre. | AR23: Tokyo National Museum (~14 min a pie) | Kanda Myojin (~15 min a pie) | Retro game hunt: Super Potato + Mandarake (~16 min a pie) | AS23: Popular / turístico | AU23: https://www.google.com/maps/search/?api=1&query=Ameyoko%2C%20Taito%2C%20Japan | AV23: 2026-09-01 | AW23: CALENDARIO / CONDICIÓN PENDIENTE | AX23: No hay cierre específico confirmado para la ventana, pero horarios o acceso pueden variar. | AY23: Reconfirmar en la web oficial al fijar fechas.
A24: JP-023 | B24: Tokio | C24: Kanto | D24: Tokio | E24: Taito | F24: Yanaka | G24: Ueno–Yanaka | H24: Yanaka Ginza and cemetery lanes | I24: 谷中銀座・谷中霊園 | J24: Yanaka Ginza and cemetery lanes | K24: 🏙️ Ciudad y barrios | L24: barrio/paseo | M24: A | N24: Shitamachi tranquilo, vivido y fotogénico sin parecer un decorado. | O24: Calle comercial baja, templos, cementerio y casas antiguas. | P24: Conserva escala residencial previa a los rascacielos. | Q24: Calle comercial baja, templos, cementerio y casas antiguas. | R24: 2–3 h | S24: Tarde | T24: Primavera y otoño | U24: Medio | V24: Medio | W24: 0 | X24: 0 | Y24: =W24*'Configuración'!$B$4 | Z24: =X24*'Configuración'!$B$4 | AA24: No | AB24: — | AC24: Espacio público; tiendas variables | AD24: Sin cierre | AE24: Nippori / Sendagi | AF24: Buena en áreas principales; confirmar detalles con el recinto | AG24: 35.7275 | AH24: 139.7668 | AI24: https://www.gotokyo.org/en/index.html | AJ24: Cambiante | AK24: HIDDEN GEM | AL24: pareja, fotografía, barrios, comida | AM24: 4 | AN24: 5 | AO24: 5 | AP24: 2 | AQ24: Imagen ideal: conserva escala residencial previa a los rascacielos. con luz de tarde, sin multitudes dominando el encuadre. | AR24: Nezu Shrine (~14 min a pie) | Tokyo National Museum (~18 min a pie) | Ameyoko (~29 min en transporte) | AS24: Semi-hidden | AU24: https://www.google.com/maps/search/?api=1&query=Yanaka%20Ginza%20and%20cemetery%20lanes%2C%20Taito%2C%20Japan | AV24: 2026-09-01 | AW24: CALENDARIO / CONDICIÓN PENDIENTE | AX24: No hay cierre específico confirmado para la ventana, pero horarios o acceso pueden variar. | AY24: Reconfirmar en la web oficial al fijar fechas.
A25: JP-024 | B25: Tokio | C25: Kanto | D25: Tokio | E25: Bunkyo | F25: Nezu | G25: Ueno–Yanaka | H25: Nezu Shrine | I25: 根津神社 | J25: Nezu Shrine | K25: ⛩️ Templos y santuarios | L25: santuario | M25: A | N25: Santuario histórico con túnel de torii y azaleas, mucho menos saturado que Fushimi Inari. | O25: Recinto Edo con estanques, torii rojos y jardín de azaleas. | P25: Ofrece imágenes de torii en un entorno local compacto. | Q25: Recinto Edo con estanques, torii rojos y jardín de azaleas. | R25: 45–90 min | S25: Mañana | T25: Abril–mayo para azaleas | U25: Medio | V25: Bajo | W25: 0 | X25: 500 | Y25: =W25*'Configuración'!$B$4 | Z25: =X25*'Configuración'!$B$4 | AA25: No | AB25: — | AC25: Aprox. 06:00–17:00 | AD25: Sin cierre ordinario | AE25: Nezu / Sendagi | AF25: Parcial; pueden existir escalones, grava o edificios sin elevador | AG25: 35.7202 | AH25: 139.7609 | AI25: https://www.nedujinja.or.jp/ | AJ25: Cambiante | AK25: ALTERNATIVE | AL25: cultura, fotografía, flores | AM25: 4 | AN25: 5 | AO25: 5 | AP25: 2 | AQ25: Imagen ideal: ofrece imágenes de torii en un entorno local compacto. con luz de mañana, sin multitudes dominando el encuadre. | AR25: Yanaka Ginza and cemetery lanes (~14 min a pie) | Tokyo National Museum (~20 min a pie) | Ameyoko (~23 min a pie) | AS25: Alternativa menos saturada | AT25: Fushimi Inari (escala mucho menor) | AU25: https://www.google.com/maps/search/?api=1&query=Nezu%20Shrine%2C%20Bunkyo%2C%20Japan | AV25: 2026-09-01 | AW25: CALENDARIO / CONDICIÓN PENDIENTE | AX25: No hay cierre específico confirmado para la ventana, pero horarios o acceso pueden variar. | AY25: Reconfirmar en la web oficial al fijar fechas.
A26: JP-025 | B26: Tokio | C26: Kanto | D26: Tokio | E26: Chiyoda | F26: Akihabara | G26: Akihabara–Kanda | H26: Akihabara Electric Town | I26: 秋葉原電気街 | J26: Akihabara Electric Town | K26: 👾 Anime/manga | L26: barrio | M26: S | N26: Sigue siendo el ecosistema pop más denso y singular para gaming, anime y electrónica. | O26: Calles de tiendas, arcades, figuras, manga, PC y cultura otaku. | P26: La variedad exige explorar edificios y callejones, no solo Chuo-dori. | Q26: Calles de tiendas, arcades, figuras, manga, PC y cultura otaku. | R26: 3–6 h | S26: Tarde | T26: Todo el año | U26: Extremo | V26: Extremo | W26: 0 | X26: 0 | Y26: =W26*'Configuración'!$B$4 | Z26: =X26*'Configuración'!$B$4 | AA26: No | AB26: — | AC26: Tiendas aprox. 10:00–21:00 | AD26: Según comercio | AE26: JR/Metro Akihabara | AF26: Buena en áreas principales; confirmar detalles con el recinto | AG26: 35.6984 | AH26: 139.7731 | AI26: https://www.gotokyo.org/en/spot/55/index.html | AJ26: Cambiante | AK26: MUST SEE / ANIME | AL26: videojuegos, anime, compras, tecnología | AM26: 5 | AN26: 5 | AO26: 4 | AP26: 5 | AQ26: Imagen ideal: la variedad exige explorar edificios y callejones, no solo chuo-dori. con luz de tarde, sin multitudes dominando el encuadre. | AR26: Retro game hunt: Super Potato + Mandarake (~4 min a pie) | Kanda Myojin (~9 min a pie) | Ameyoko (~18 min a pie) | AS26: Popular / turístico | AU26: https://www.google.com/maps/search/?api=1&query=Akihabara%20Electric%20Town%2C%20Chiyoda%2C%20Japan | AV26: 2026-09-01 | AW26: CALENDARIO / CONDICIÓN PENDIENTE | AX26: No hay cierre específico confirmado para la ventana, pero horarios o acceso pueden variar. | AY26: Reconfirmar en la web oficial al fijar fechas.
A27: JP-026 | B27: Tokio | C27: Kanto | D27: Tokio | E27: Chiyoda | F27: Akihabara | G27: Akihabara–Kanda | H27: Retro game hunt: Super Potato + Mandarake | I27: スーパーポテト・まんだらけ | J27: Retro game hunt: Super Potato + Mandarake | K27: 🎮 Videojuegos | L27: experiencia de compras | M27: A | N27: Excelente para historia material del videojuego, aunque precios de coleccionista pueden ser altos. | O27: Búsqueda de consolas, cartuchos, revistas, figuras y memorabilia retro. | P27: Permite comparar varias generaciones de cultura de juego japonesa. | Q27: Búsqueda de consolas, cartuchos, revistas, figuras y memorabilia retro. | R27: 1.5–3 h | S27: Tarde | T27: Todo el año | U27: Alto | V27: Alto | W27: 0 | X27: 0 | Y27: =W27*'Configuración'!$B$4 | Z27: =X27*'Configuración'!$B$4 | AA27: No | AB27: — | AC27: Según tienda, aprox. 11:00–20:00 | AD27: Según tienda | AE27: JR Akihabara | AF27: Buena en áreas principales; confirmar detalles con el recinto | AG27: 35.7005 | AH27: 139.7714 | AI27: https://www.gotokyo.org/en/index.html | AJ27: Cambiante | AK27: GAMING | AL27: videojuegos, compras, nostalgia | AM27: 4 | AN27: 5 | AO27: 4 | AP27: 4 | AQ27: Imagen ideal: permite comparar varias generaciones de cultura de juego japonesa. con luz de tarde, sin multitudes dominando el encuadre. | AR27: Akihabara Electric Town (~4 min a pie) | Kanda Myojin (~5 min a pie) | Ameyoko (~16 min a pie) | AS27: Popular / turístico | AU27: https://www.google.com/maps/search/?api=1&query=Retro%20game%20hunt%3A%20Super%20Potato%20%2B%20Mandarake%2C%20Chiyoda%2C%20Japan | AV27: 2026-09-01 | AW27: CALENDARIO / CONDICIÓN PENDIENTE | AX27: No hay cierre específico confirmado para la ventana, pero horarios o acceso pueden variar. | AY27: Reconfirmar en la web oficial al fijar fechas.
A28: JP-027 | B28: Tokio | C28: Kanto | D28: Tokio | E28: Chiyoda | F28: Kanda | G28: Akihabara–Kanda | H28: Kanda Myojin | I28: 神田明神 | J28: Kanda Myojin | K28: ⛩️ Templos y santuarios | L28: santuario | M28: A | N28: Puente convincente entre tradición, negocios y cultura anime. | O28: Santuario histórico protector de Kanda y Akihabara. | P28: Vende amuletos de tecnología y colabora con franquicias pop. | Q28: Santuario histórico protector de Kanda y Akihabara. | R28: 45–75 min | S28: Mañana | T28: Todo el año | U28: Medio | V28: Medio | W28: 0 | X28: 0 | Y28: =W28*'Configuración'!$B$4 | Z28: =X28*'Configuración'!$B$4 | AA28: No | AB28: — | AC28: Recinto amplio; oficinas diurnas | AD28: Sin cierre ordinario | AE28: Ochanomizu / Suehirocho | AF28: Parcial; pueden existir escalones, grava o edificios sin elevador | AG28: 35.702 | AH28: 139.7679 | AI28: https://www.kandamyoujin.or.jp/english/ | AJ28: Cambiante | AK28: CULTURE + TECH | AL28: anime, cultura, fotografía | AM28: 4 | AN28: 5 | AO28: 5 | AP28: 2 | AQ28: Imagen ideal: vende amuletos de tecnología y colabora con franquicias pop. con luz de mañana, sin multitudes dominando el encuadre. | AR28: Retro game hunt: Super Potato + Mandarake (~5 min a pie) | Akihabara Electric Town (~9 min a pie) | Ameyoko (~15 min a pie) | AS28: Semi-hidden | AU28: https://www.google.com/maps/search/?api=1&query=Kanda%20Myojin%2C%20Chiyoda%2C%20Japan | AV28: 2026-09-01 | AW28: CALENDARIO / CONDICIÓN PENDIENTE | AX28: No hay cierre específico confirmado para la ventana, pero horarios o acceso pueden variar. | AY28: Reconfirmar en la web oficial al fijar fechas.
A29: JP-028 | B29: Tokio | C29: Kanto | D29: Tokio | E29: Chiyoda | F29: Jimbocho | G29: Jimbocho | H29: Jimbocho Book Town | I29: 神保町古書店街 | J29: Jimbocho Book Town | K29: 🛍️ Compras | L29: barrio de librerías | M29: A | N29: Especialización y atmósfera intelectual difíciles de encontrar en otra megaciudad. | O29: Centenares de librerías nuevas, usadas, mapas, cine y arte. | P29: Los escaparates y cafés conservan una cultura urbana no diseñada para turistas. | Q29: Centenares de librerías nuevas, usadas, mapas, cine y arte. | R29: 2–4 h | S29: Tarde | T29: Días laborables/sábado | U29: Bajo | V29: Bajo | W29: 0 | X29: 0 | Y29: =W29*'Configuración'!$B$4 | Z29: =X29*'Configuración'!$B$4 | AA29: No | AB29: — | AC29: Tiendas aprox. 10:00–19:00 | AD29: Muchos domingos | AE29: Metro Jimbocho | AF29: Buena en áreas principales; confirmar detalles con el recinto | AG29: 35.6956 | AH29: 139.7576 | AI29: https://www.gotokyo.org/en/index.html | AJ29: Cambiante | AK29: HIDDEN GEM | AL29: libros, arte, cafés, lluvia | AM29: 3 | AN29: 5 | AO29: 5 | AP29: 1 | AQ29: Imagen ideal: los escaparates y cafés conservan una cultura urbana no diseñada para turistas. con luz de tarde, sin multitudes dominando el encuadre. | AR29: Kanda Myojin (~16 min a pie) | Imperial Palace East Gardens (~17 min a pie) | Retro game hunt: Super Potato + Mandarake (~19 min a pie) | AS29: Hidden Gem real | AU29: https://www.google.com/maps/search/?api=1&query=Jimbocho%20Book%20Town%2C%20Chiyoda%2C%20Japan | AV29: 2026-09-01 | AW29: CALENDARIO / CONDICIÓN PENDIENTE | AX29: No hay cierre específico confirmado para la ventana, pero horarios o acceso pueden variar. | AY29: Reconfirmar en la web oficial al fijar fechas.
A30: JP-029 | B30: Tokio | C30: Kanto | D30: Tokio | E30: Chiyoda | F30: Marunouchi | G30: Marunouchi–Ginza | H30: Imperial Palace East Gardens | I30: 皇居東御苑 | J30: Imperial Palace East Gardens | K30: 🌸 Jardines y paisajes | L30: jardín histórico | M30: A | N30: Paisaje, murallas y vacío urbano de gran escala sin costo. | O30: Jardines del antiguo Edo Castle dentro del recinto imperial. | P30: Permite entender la topografía política de Tokio. | Q30: Jardines del antiguo Edo Castle dentro del recinto imperial. | R30: 1.5–2.5 h | S30: Mañana | T30: Primavera y otoño | U30: Medio | V30: Medio | W30: 0 | X30: 0 | Y30: =W30*'Configuración'!$B$4 | Z30: =X30*'Configuración'!$B$4 | AA30: No | AB30: — | AC30: 09:00–16:30/17:00 según temporada | AD30: Lunes, viernes y actos; verificar | AE30: Otemachi / Takebashi | AF30: Parcial; pueden existir escalones, grava o edificios sin elevador | AG30: 35.6852 | AH30: 139.7528 | AI30: https://www.kunaicho.go.jp/e-event/higashigyoen.html | AJ30: Cambiante | AK30: HISTORY | AL30: historia, jardines, fotografía | AM30: 4 | AN30: 4 | AO30: 5 | AP30: 2 | AQ30: Imagen ideal: permite entender la topografía política de tokio. con luz de mañana, sin multitudes dominando el encuadre. | AR30: Jimbocho Book Town (~17 min a pie) | Tokyo Station Marunouchi Building (~19 min a pie) | Kagurazaka backstreets (~30 min en transporte) | AS30: Lugar conocido pero excelente | AU30: https://www.google.com/maps/search/?api=1&query=Imperial%20Palace%20East%20Gardens%2C%20Chiyoda%2C%20Japan | AV30: 2026-09-01 | AW30: CALENDARIO / CONDICIÓN PENDIENTE | AX30: No hay cierre específico confirmado para la ventana, pero horarios o acceso pueden variar. | AY30: Reconfirmar en la web oficial al fijar fechas.
A31: JP-030 | B31: Tokio | C31: Kanto | D31: Tokio | E31: Chiyoda | F31: Marunouchi | G31: Marunouchi–Ginza | H31: Tokyo Station Marunouchi Building | I31: 東京駅丸の内駅舎 | J31: Tokyo Station Marunouchi Building | K31: 🏙️ Ciudad y barrios | L31: arquitectura/estación | M31: A | N31: Nodo funcional y monumento urbano; excelente punto visual de día y noche. | O31: Fachada histórica restaurada, cúpulas y eje hacia el Palacio Imperial. | P31: Combina infraestructura ferroviaria viva con arquitectura de 1914. | Q31: Fachada histórica restaurada, cúpulas y eje hacia el Palacio Imperial. | R31: 30–75 min | S31: Noche | T31: Todo el año | U31: Extremo | V31: Alto | W31: 0 | X31: 0 | Y31: =W31*'Configuración'!$B$4 | Z31: =X31*'Configuración'!$B$4 | AA31: No | AB31: — | AC31: Estación 24 h; comercios variables | AD31: Sin cierre | AE31: JR/Metro Tokyo | AF31: Buena en áreas principales; confirmar detalles con el recinto | AG31: 35.6812 | AH31: 139.7671 | AI31: https://www.tokyostationcity.com/en/ | AJ31: Cambiante | AK31: ARCHITECTURE | AL31: arquitectura, trenes, fotografía | AM31: 5 | AN31: 4 | AO31: 5 | AP31: 4 | AQ31: Imagen ideal: combina infraestructura ferroviaria viva con arquitectura de 1914. con luz de noche, sin multitudes dominando el encuadre. | AR31: Imperial Palace East Gardens (~19 min a pie) | Tsukiji Outer Market (~25 min a pie) | Jimbocho Book Town (~25 min en transporte) | AS31: Popular / turístico | AU31: https://www.google.com/maps/search/?api=1&query=Tokyo%20Station%20Marunouchi%20Building%2C%20Chiyoda%2C%20Japan | AV31: 2026-09-01 | AW31: CALENDARIO / CONDICIÓN PENDIENTE | AX31: No hay cierre específico confirmado para la ventana, pero horarios o acceso pueden variar. | AY31: Reconfirmar en la web oficial al fijar fechas.
A32: JP-031 | B32: Tokio | C32: Kanto | D32: Tokio | E32: Chuo | F32: Shiodome | G32: Marunouchi–Ginza | H32: Hama-rikyu Gardens | I32: 浜離宮恩賜庭園 | J32: Hama-rikyu Gardens | K32: 🌸 Jardines y paisajes | L32: jardín | M32: A | N32: Uno de los mejores contrastes entre jardín feudal, agua salada y rascacielos. | O32: Jardín daimyō con estanque mareal y casa de té. | P32: La marea de la bahía altera el paisaje interior. | Q32: Jardín daimyō con estanque mareal y casa de té. | R32: 1.5–2.5 h | S32: Mañana | T32: Colza, peonías y otoño | U32: Medio | V32: Medio | W32: 300 | X32: 300 | Y32: =W32*'Configuración'!$B$4 | Z32: =X32*'Configuración'!$B$4 | AA32: No | AB32: — | AC32: 09:00–17:00 | AD32: Fin de año; verificar | AE32: Shiodome / Tsukijishijo | AF32: Parcial; pueden existir escalones, grava o edificios sin elevador | AG32: 35.6597 | AH32: 139.7635 | AI32: https://www.tokyo-park.or.jp/park/hama-rikyu/ | AJ32: Cambiante | AK32: GARDEN | AL32: pareja, jardines, cultura, fotografía | AM32: 5 | AN32: 5 | AO32: 5 | AP32: 2 | AQ32: Imagen ideal: la marea de la bahía altera el paisaje interior. con luz de mañana, sin multitudes dominando el encuadre. | AR32: Tsukiji Outer Market (~13 min a pie) | Zōjō-ji + Tokyo Tower view (~20 min a pie) | teamLab Borderless (~29 min en transporte) | AS32: Semi-hidden | AU32: https://www.google.com/maps/search/?api=1&query=Hama-rikyu%20Gardens%2C%20Chuo%2C%20Japan | AV32: 2026-09-01 | AW32: CALENDARIO / CONDICIÓN PENDIENTE | AX32: No hay cierre específico confirmado para la ventana, pero horarios o acceso pueden variar. | AY32: Reconfirmar en la web oficial al fijar fechas.
A33: JP-032 | B33: Tokio | C33: Kanto | D33: Tokio | E33: Chuo | F33: Tsukiji | G33: Marunouchi–Ginza | H33: Tsukiji Outer Market | I33: 築地場外市場 | J33: Tsukiji Outer Market | K33: 🍜 Gastronomía | L33: mercado gastronómico | M33: C | N33: Sigue teniendo buenos especialistas, pero filas, sobreprecio y oferta viral reducen el valor. | O33: Calles de pescaderías, desayunos, cuchillos y productos secos. | P33: El antiguo mercado mayorista ya no opera aquí; conviene seleccionar negocios concretos. | Q33: Calles de pescaderías, desayunos, cuchillos y productos secos. | R33: 1–2 h | S33: Mañana | T33: Días laborables/sábado | U33: Extremo | V33: Extremo | W33: 1000 | X33: 6000 | Y33: =W33*'Configuración'!$B$4 | Z33: =X33*'Configuración'!$B$4 | AA33: No | AB33: — | AC33: Muchos locales 06:00–14:00 | AD33: Miércoles/domingo variable | AE33: Tsukiji / Tsukijishijo | AF33: Buena en áreas principales; confirmar detalles con el recinto | AG33: 35.6655 | AH33: 139.7707 | AI33: https://www.tsukiji.or.jp/english/ | AJ33: Cambiante | AK33: FOOD / TOURISTY | AL33: comida, mercado | AM33: 3 | AN33: 2 | AO33: 2 | AP33: 5 | AQ33: Imagen ideal: el antiguo mercado mayorista ya no opera aquí; conviene seleccionar negocios concretos. con luz de mañana, sin multitudes dominando el encuadre. | AR33: Hama-rikyu Gardens (~13 min a pie) | Tokyo Station Marunouchi Building (~25 min a pie) | Zōjō-ji + Tokyo Tower view (~31 min en transporte) | AS33: Popular / turístico | AU33: https://www.google.com/maps/search/?api=1&query=Tsukiji%20Outer%20Market%2C%20Chuo%2C%20Japan | AV33: 2026-09-01 | AW33: CALENDARIO / CONDICIÓN PENDIENTE | AX33: No hay cierre específico confirmado para la ventana, pero horarios o acceso pueden variar. | AY33: Reconfirmar en la web oficial al fijar fechas.
A34: JP-033 | B34: Tokio | C34: Kanto | D34: Tokio | E34: Minato | F34: Azabudai | G34: Roppongi–Azabudai | H34: teamLab Borderless | I34: チームラボボーダレス | J34: teamLab Borderless | K34: 🎨 Arte | L34: museo inmersivo | M34: S | N34: La experiencia digital más libre y exploratoria de Tokio. | O34: Museo sin mapa de instalaciones audiovisuales interconectadas. | P34: Las obras migran entre salas y premian perderse, a diferencia de un recorrido lineal. | Q34: Museo sin mapa de instalaciones audiovisuales interconectadas. | R34: 2.5–4 h | S34: Mañana | T34: Todo el año | U34: Extremo | V34: Extremo | W34: 3600 | X34: 5600 | Y34: =W34*'Configuración'!$B$4 | Z34: =X34*'Configuración'!$B$4 | AA34: Sí | AB34: 2–4 semanas | AC34: Horario variable por fecha | AD34: Variable | AE34: Kamiyacho / Roppongi-itchome | AF34: Buena en áreas principales; confirmar detalles con el recinto | AG34: 35.6605 | AH34: 139.7405 | AI34: https://www.teamlab.art/e/tokyo/ | AJ34: Cambiante | AK34: MUST SEE / ART | AL34: pareja, arte, tecnología, fotografía | AM34: 5 | AN34: 5 | AO34: 4 | AP34: 5 | AQ34: Imagen ideal: las obras migran entre salas y premian perderse, a diferencia de un recorrido lineal. con luz de mañana, sin multitudes dominando el encuadre. | AR34: Zōjō-ji + Tokyo Tower view (~11 min a pie) | Mori Art Museum + Tokyo City View (~14 min a pie) | 21_21 DESIGN SIGHT (~17 min a pie) | AS34: Popular / turístico | AU34: https://www.google.com/maps/search/?api=1&query=teamLab%20Borderless%2C%20Minato%2C%20Japan | AV34: 2026-09-01 | AW34: ABIERTO CONFIRMADO | AX34: Sede permanente en Azabudai Hills desde 2024; no es la antigua sede de Odaiba y no fue sustituida por Planets. | AY34: Comprar franja horaria y reconfirmar horario/precio de la fecha.
